Workbook

Sheet DASHBOARD
C2: SCENARIO | D2: Base | H2: Pessmistic | I2: Base | J2: Optmistic
C3: Choose Base/Pessimistic/Optimistic Scenarios, the Financial model Updates automatially

Sheet FS
B2: Years (As on March) | C2: 2017 | D2: =C2+1 -> 2018 | E2: =D2+1 -> 2019 | F2: =E2+1 -> 2020 | G2: =F2+1 -> 2021 | H2: =G2+1 -> 2022 | I2: =H2+1 -> 2023 | J2: =I2+1 -> 2024 | K2: =J2+1 -> 2025 | ... Q2: =P2+1 -> 2031 | S2: CAGR
B3: Revenue | C3: ='Forecast Drivers'!C7 -> 59289 | D3: ='Forecast Drivers'!D7 -> 61941 | E3: ='Forecast Drivers'!E7 -> 73107 | F3: ='Forecast Drivers'!F7 -> 79047 | G3: ='Forecast Drivers'!G7 -> 85912 | H3: ='Forecast Drivers'!H7 -> 103940 | I3: ='Forecast Drivers'!I7 -> 124014 | J3: ='Forecast Drivers'!J7 -> 128933 | ... Q3: ='Forecast Drivers'!Q7 -> 217072.46 | S3: =_xlfn.RRI(5,L3,Q3) -> 0.078423314
B5: Clients | C5: ='Forecast Drivers'!C9 -> 1162 | D5: ='Forecast Drivers'!D9 -> 1204 | E5: ='Forecast Drivers'!E9 -> 1279 | F5: ='Forecast Drivers'!F9 -> 1411 | G5: ='Forecast Drivers'!G9 -> 1626 | H5: ='Forecast Drivers'!H9 -> 1741 | I5: ='Forecast Drivers'!I9 -> 1872 | J5: ='Forecast Drivers'!J9 -> 1882 | ... Q5: ='Forecast Drivers'!Q9 -> 2291.9487 | S5: =_xlfn.RRI(5,L5,Q5) -> 0.031260703
B7: EBITDA | C7: ='Forecast Drivers'!C7-'Forecast Drivers'!C32-'Forecast Drivers'!C47 -> 17207 | D7: ='Forecast Drivers'!D7-'Forecast Drivers'!D32-'Forecast Drivers'!D47 -> 17297 | E7: ='Forecast Drivers'!E7-'Forecast Drivers'!E32-'Forecast Drivers'!E47 -> 18674 | F7: ='Forecast Drivers'!F7-'Forecast Drivers'!F32-'Forecast Drivers'!F47 -> 20035 | G7: ='Forecast Drivers'!G7-'Forecast Drivers'!G32-'Forecast Drivers'!G47 -> 24457 | H7: ='Forecast Drivers'!H7-'Forecast Drivers'!H32-'Forecast Drivers'!H47 -> 27828 | I7: ='Forecast Drivers'!I7-'Forecast Drivers'!I32-'Forecast Drivers'!I47 -> 30694 | J7: ='Forecast Drivers'!J7-'Forecast Drivers'!J32-'Forecast Drivers'!J47 -> 31757 | ... Q7: ='Forecast Drivers'!Q7-'Forecast Drivers'!Q32-'Forecast Drivers'!Q47 -> 58479.607 | S7: =_xlfn.RRI(5,L7,Q7) -> 0.10181588
B11: Years (As on March) | C11: 2017 | D11: =C11+1 -> 2018 | E11: =D11+1 -> 2019 | F11: =E11+1 -> 2020 | G11: =F11+1 -> 2021 | H11: =G11+1 -> 2022 | I11: =H11+1 -> 2023 | J11: =I11+1 -> 2024 | K11: =J11+1 -> 2025 | ... Q11: =P11+1 -> 2031
B12: Revenue | C12: =C3 -> 59289 | D12: =D3 -> 61941 | E12: =E3 -> 73107 | F12: =F3 -> 79047 | G12: =G3 -> 85912 | H12: =H3 -> 103940 | I12: =I3 -> 124014 | J12: =J3 -> 128933 | ... Q12: =Q3 -> 217072.46
B13: EBITDA | C13: =C7 -> 17207 | D13: =D7 -> 17297 | E13: =E7 -> 18674 | F13: =F7 -> 20035 | G13: =G7 -> 24457 | H13: =H7 -> 27828 | I13: =I7 -> 30694 | J13: =J7 -> 31757 | ... Q13: =Q7 -> 58479.607
B16: Years (As on March) | C16: 2017 | D16: =C16+1 -> 2018 | E16: =D16+1 -> 2019 | F16: =E16+1 -> 2020 | G16: =F16+1 -> 2021 | H16: =G16+1 -> 2022 | I16: =H16+1 -> 2023 | J16: =I16+1 -> 2024 | K16: =J16+1 -> 2025 | ... Q16: =P16+1 -> 2031
B17: Clients | C17: =C5 -> 1162 | D17: =D5 -> 1204 | E17: =E5 -> 1279 | F17: =F5 -> 1411 | G17: =G5 -> 1626 | H17: =H5 -> 1741 | I17: =I5 -> 1872 | J17: =J5 -> 1882 | ... Q17: =Q5 -> 2291.9487
B19: Years (As on March) | C19: 2017 | D19: =C19+1 -> 2018 | E19: =D19+1 -> 2019 | F19: =E19+1 -> 2020 | G19: =F19+1 -> 2021 | H19: =G19+1 -> 2022 | I19: =H19+1 -> 2023 | J19: =I19+1 -> 2024 | K19: =J19+1 -> 2025 | ... Q19: =P19+1 -> 2031
B20: Large clients ( >50 M $) | C20: ='Forecast Drivers'!C16 -> 75 | D20: ='Forecast Drivers'!D16 -> 77 | E20: ='Forecast Drivers'!E16 -> 85 | F20: ='Forecast Drivers'!F16 -> 28 | G20: ='Forecast Drivers'!G16 -> 32 | H20: ='Forecast Drivers'!H16 -> 38 | I20: ='Forecast Drivers'!I16 -> 115 | J20: ='Forecast Drivers'!J16 -> 123 | ... Q20: ='Forecast Drivers'!Q16 -> 169.5649
B22: Years (As on March) | C22: 2017 | D22: =C22+1 -> 2018 | E22: =D22+1 -> 2019 | F22: =E22+1 -> 2020 | G22: =F22+1 -> 2021 | H22: =G22+1 -> 2022 | I22: =H22+1 -> 2023 | J22: =I22+1 -> 2024 | K22: =J22+1 -> 2025 | ... Q22: =P22+1 -> 2031
B23: Other clients | C23: ='Forecast Drivers'!C23 -> 1087 | D23: ='Forecast Drivers'!D23 -> 1127 | E23: ='Forecast Drivers'!E23 -> 1194 | F23: ='Forecast Drivers'!F23 -> 1383 | G23: ='Forecast Drivers'!G23 -> 1594 | H23: ='Forecast Drivers'!H23 -> 1703 | I23: ='Forecast Drivers'!I23 -> 1757 | J23: ='Forecast Drivers'!J23 -> 1759 | ... Q23: ='Forecast Drivers'!Q23 -> 2356.7421
B24: Large clients ( >50 M $) | C24: =C20 -> 75 | D24: =D20 -> 77 | E24: =E20 -> 85 | F24: =F20 -> 28 | G24: =G20 -> 32 | H24: =H20 -> 38 | I24: =I20 -> 115 | J24: =J20 -> 123 | ... Q24: =Q20 -> 169.5649
B28: Particulars | C28: Infosys | D28: TCS | E28: HCL | F28: Wipro
B29: EV/EBITDA | C29: ='EV-EBITDA'!C14 -> 12.752719 | D29: ='EV-EBITDA'!D14 -> 11.68647 | E29: ='EV-EBITDA'!E14 -> 20.703031 | F29: ='EV-EBITDA'!F14 -> 10.599802
B31: Years (As on March) | C31: 2017 | D31: =C31+1 -> 2018 | E31: =D31+1 -> 2019 | F31: =E31+1 -> 2020 | G31: =F31+1 -> 2021 | H31: =G31+1 -> 2022 | I31: =H31+1 -> 2023 | J31: =I31+1 -> 2024 | K31: =J31+1 -> 2025 | ... Q31: =P31+1 -> 2031
B32: Revenue per employee | C32: =C36/$C$36*100 -> 100 | D32: =D36/$C$36*100 -> 102.55714 | E32: =E36/$C$36*100 -> 108.30175 | F32: =F36/$C$36*100 -> 110.21744 | G32: =G36/$C$36*100 -> 111.83118 | H32: =H36/$C$36*100 -> 111.86079 | I32: =I36/$C$36*100 -> 122.1029 | J32: =J36/$C$36*100 -> 137.3478 | ... Q32: =Q36/$C$36*100 -> 204.45898
B33: Employee cost per employee | C33: =C37/$C$37*100 -> 100 | D33: =D37/$C$37*100 -> 103.01215 | E33: =E37/$C$37*100 -> 108.68777 | F33: =F37/$C$37*100 -> 113.35277 | G33: =G37/$C$37*100 -> 112.6613 | H33: =H37/$C$37*100 -> 106.52389 | I33: =I37/$C$37*100 -> 118.39709 | J33: =J37/$C$37*100 -> 132.94645 | ... Q33: =Q37/$C$37*100 -> 177.45842
B36: Revenue per employee | C36: ='Forecast Drivers'!C7/'Forecast Drivers'!C36 -> 0.29590645 | D36: ='Forecast Drivers'!D7/'Forecast Drivers'!D36 -> 0.30347318 | E36: ='Forecast Drivers'!E7/'Forecast Drivers'!E36 -> 0.32047185 | F36: ='Forecast Drivers'!F7/'Forecast Drivers'!F36 -> 0.3261405 | G36: ='Forecast Drivers'!G7/'Forecast Drivers'!G36 -> 0.33091569 | H36: ='Forecast Drivers'!H7/'Forecast Drivers'!H36 -> 0.3310033 | I36: ='Forecast Drivers'!I7/'Forecast Drivers'!I36 -> 0.36131036 | J36: ='Forecast Drivers'!J7/'Forecast Drivers'!J36 -> 0.40642101 | ... Q36: ='Forecast Drivers'!Q7/'Forecast Drivers'!Q36 -> 0.60500731
B37: Employee cost per employee | C37: ='Forecast Drivers'!C39 -> 0.15448384 | D37: ='Forecast Drivers'!D39 -> 0.15913712 | E37: ='Forecast Drivers'!E39 -> 0.16790503 | F37: ='Forecast Drivers'!F39 -> 0.17511171 | G37: ='Forecast Drivers'!G39 -> 0.1740435 | H37: ='Forecast Drivers'!H39 -> 0.1645622 | I37: ='Forecast Drivers'!I39 -> 0.18290437 | J37: ='Forecast Drivers'!J39 -> 0.20538078 | ... Q37: ='Forecast Drivers'!Q39 -> 0.27414459

Sheet Financials>>

Sheet Historical FS
L1: in CR
B2: ='DATA Sheet'!B1&" Historical FS" -> INFOSYS LTD Historical FS
B3: Years | C3: FY17 | D3: FY18 | E3: FY19 | F3: FY20 | G3: FY21 | H3: FY22 | I3: FY23 | J3: FY24 | K3: FY25 | L3: FY26
A4: # | B4: Income Statement
B5: Sales | C5: ='DATA Sheet'!B17 -> 59289 | D5: ='DATA Sheet'!C17 -> 61941 | E5: ='DATA Sheet'!D17 -> 73107 | F5: ='DATA Sheet'!E17 -> 79047 | G5: ='DATA Sheet'!F17 -> 85912 | H5: ='DATA Sheet'!G17 -> 103940 | I5: ='DATA Sheet'!H17 -> 124014 | J5: ='DATA Sheet'!I17 -> 128933 | ... L5: ='DATA Sheet'!K17 -> 148819
B6: Sales Growth | D6: =D5/C5-1 -> 0.044730051 | E6: =E5/D5-1 -> 0.18026832 | F6: =F5/E5-1 -> 0.081250769 | G6: =G5/F5-1 -> 0.086847066 | H6: =H5/G5-1 -> 0.20984263 | I6: =I5/H5-1 -> 0.19313065 | J6: =J5/I5-1 -> 0.039664877 | K6: =K5/J5-1 -> 0.059402946 | L6: =L5/K5-1 -> 0.089514759
B8: COGS | C8: =SUM('DATA Sheet'!B18:B22) -> 38281 | D8: =SUM('DATA Sheet'!C18:C22) -> 40331 | E8: =SUM('DATA Sheet'!D18:D22) -> 48850 | F8: =SUM('DATA Sheet'!E18:E22) -> 53988 | G8: =SUM('DATA Sheet'!F18:F22) -> 57966 | H8: =SUM('DATA Sheet'!G18:G22) -> 71916 | I8: =SUM('DATA Sheet'!H18:H22) -> 88211 | J8: =SUM('DATA Sheet'!I18:I22) -> 91832 | ... L8: =SUM('DATA Sheet'!K18:K22) -> 106285
B9: % of sales | C9: =C8/C5 -> 0.64566783 | D9: =D8/D5 -> 0.65111961 | E9: =E8/E5 -> 0.66819867 | F9: =F8/F5 -> 0.68298607 | G9: =G8/G5 -> 0.67471366 | H9: =H8/H5 -> 0.69189917 | I9: =I8/I5 -> 0.71129872 | J9: =J8/J5 -> 0.7122459 | ... L9: =L8/L5 -> 0.71418972
B11: Gross Profit | C11: =C5-C8 -> 21008 | D11: =D5-D8 -> 21610 | E11: =E5-E8 -> 24257 | F11: =F5-F8 -> 25059 | G11: =G5-G8 -> 27946 | H11: =H5-H8 -> 32024 | I11: =I5-I8 -> 35803 | J11: =J5-J8 -> 37101 | ... L11: =L5-L8 -> 42534
B12: Gross margin | C12: =C11/C5 -> 0.35433217 | D12: =D11/D5 -> 0.34888039 | E12: =E11/E5 -> 0.33180133 | F12: =F11/F5 -> 0.31701393 | G12: =G11/G5 -> 0.32528634 | H12: =H11/H5 -> 0.30810083 | I12: =I11/I5 -> 0.28870128 | J12: =J11/J5 -> 0.2877541 | ... L12: =L11/L5 -> 0.28581028
B15: SG&A | C15: ='DATA Sheet'!B23+'DATA Sheet'!B24 -> 3801 | D15: ='DATA Sheet'!C23+'DATA Sheet'!C24 -> 4313 | E15: ='DATA Sheet'!D23+'DATA Sheet'!D24 -> 5583 | F15: ='DATA Sheet'!E23+'DATA Sheet'!E24 -> 5024 | G15: ='DATA Sheet'!F23+'DATA Sheet'!F24 -> 3489 | H15: ='DATA Sheet'!G23+'DATA Sheet'!G24 -> 4196 | I15: ='DATA Sheet'!H23+'DATA Sheet'!H24 -> 5109 | J15: ='DATA Sheet'!I23+'DATA Sheet'!I24 -> 5344 | ... L15: ='DATA Sheet'!K23+'DATA Sheet'!K24 -> 6521
B16: % of sales | C16: =C15/C5 -> 0.0641097 | D16: =D15/D5 -> 0.069630778 | E16: =E15/E5 -> 0.076367516 | F16: =F15/F5 -> 0.063557124 | G16: =G15/G5 -> 0.040611323 | H16: =H15/H5 -> 0.040369444 | I16: =I15/I5 -> 0.041196962 | J16: =J15/J5 -> 0.041447884 | ... L16: =L15/L5 -> 0.04381833
B18: EBITDA | C18: =C11-C15 -> 17207 | D18: =D11-D15 -> 17297 | E18: =E11-E15 -> 18674 | F18: =F11-F15 -> 20035 | G18: =G11-G15 -> 24457 | H18: =H11-H15 -> 27828 | I18: =I11-I15 -> 30694 | J18: =J11-J15 -> 31757 | ... L18: =L11-L15 -> 36013
B19: % of sales | C19: =C18/C5 -> 0.29022247 | D19: =D18/D5 -> 0.27924961 | E19: =E18/E5 -> 0.25543382 | F19: =F18/F5 -> 0.2534568 | G19: =G18/G5 -> 0.28467502 | H19: =H18/H5 -> 0.26773138 | I19: =I18/I5 -> 0.24750431 | J19: =J18/J5 -> 0.24630622 | ... L19: =L18/L5 -> 0.24199195
B22: Interest | C22: ='DATA Sheet'!B27 -> 0 | D22: ='DATA Sheet'!C27 -> 0 | E22: ='DATA Sheet'!D27 -> 0 | F22: ='DATA Sheet'!E27 -> 114 | G22: ='DATA Sheet'!F27 -> 126 | H22: ='DATA Sheet'!G27 -> 128 | I22: ='DATA Sheet'!H27 -> 157 | J22: ='DATA Sheet'!I27 -> 277 | ... L22: ='DATA Sheet'!K27 -> 207
B25: Depreciation | C25: ='DATA Sheet'!B26 -> 1331 | D25: ='DATA Sheet'!C26 -> 1408 | E25: ='DATA Sheet'!D26 -> 1599 | F25: ='DATA Sheet'!E26 -> 2144 | G25: ='DATA Sheet'!F26 -> 2321 | H25: ='DATA Sheet'!G26 -> 2429 | I25: ='DATA Sheet'!H26 -> 2753 | J25: ='DATA Sheet'!I26 -> 2944 | ... L25: ='DATA Sheet'!K26 -> 2394
B28: Other Income | C28: ='DATA Sheet'!B25 -> 3062 | D28: ='DATA Sheet'!C25 -> 4019 | E28: ='DATA Sheet'!D25 -> 2852 | F28: ='DATA Sheet'!E25 -> 2700 | G28: ='DATA Sheet'!F25 -> 2467 | H28: ='DATA Sheet'!G25 -> 3224 | I28: ='DATA Sheet'!H25 -> 3859 | J28: ='DATA Sheet'!I25 -> 7417 | ... L28: ='DATA Sheet'!K25 -> 5345
B31: PBT | C31: =C18+C28-C25-C22 -> 18938 | D31: =D18+D28-D25-D22 -> 19908 | E31: =E18+E28-E25-E22 -> 19927 | F31: =F18+F28-F25-F22 -> 20477 | G31: =G18+G28-G25-G22 -> 24477 | H31: =H18+H28-H25-H22 -> 28495 | I31: =I18+I28-I25-I22 -> 31643 | J31: =J18+J28-J25-J22 -> 35953 | ... L31: =L18+L28-L25-L22 -> 38757
B32: % of sales | C32: =C31/C5 -> 0.31941844 | D32: =D31/D5 -> 0.32140263 | E32: =E31/E5 -> 0.27257308 | F32: =F31/F5 -> 0.25904841 | G32: =G31/G5 -> 0.28490781 | H32: =H31/H5 -> 0.27414855 | I32: =I31/I5 -> 0.25515668 | J32: =J31/J5 -> 0.27885026 | ... L32: =L31/L5 -> 0.26043046
B34: Tax | C34: ='DATA Sheet'!B29 -> 5120 | D34: ='DATA Sheet'!C29 -> 3753 | E34: ='DATA Sheet'!D29 -> 5225 | F34: ='DATA Sheet'!E29 -> 4934 | G34: ='DATA Sheet'!F29 -> 6429 | H34: ='DATA Sheet'!G29 -> 7260 | I34: ='DATA Sheet'!H29 -> 8375 | J34: ='DATA Sheet'!I29 -> 8719 | ... L34: ='DATA Sheet'!K29 -> 9546
B35: Effective rate | C35: =C34/C31 -> 0.2703559 | D35: =D34/D31 -> 0.18851718 | E35: =E34/E31 -> 0.26220706 | F35: =F34/F31 -> 0.24095326 | G35: =G34/G31 -> 0.26265474 | H35: =H34/H31 -> 0.25478154 | I35: =I34/I31 -> 0.26467149 | J35: =J34/J31 -> 0.24251106 | ... L35: =L34/L31 -> 0.24630389
B37: Net profit | C37: =C31-C34 -> 13818 | D37: =D31-D34 -> 16155 | E37: =E31-E34 -> 14702 | F37: =F31-F34 -> 15543 | G37: =G31-G34 -> 18048 | H37: =H31-H34 -> 21235 | I37: =I31-I34 -> 23268 | J37: =J31-J34 -> 27234 | ... L37: =L31-L34 -> 29211
B39: Dividend | C39: ='DATA Sheet'!B31 -> 5912.2 | D39: ='DATA Sheet'!C31 -> 9500.4 | E39: ='DATA Sheet'!D31 -> 9365.4 | F39: ='DATA Sheet'!E31 -> 7451.5 | G39: ='DATA Sheet'!F31 -> 11502 | H39: ='DATA Sheet'!G31 -> 13038.6 | I39: ='DATA Sheet'!H31 -> 14103.2 | J39: ='DATA Sheet'!I31 -> 19090 | ... L39: ='DATA Sheet'!K31 -> 19459.2
B40: Dividend ratio | C40: =C39/C37 -> 0.42786221 | D40: =D39/D37 -> 0.58807799 | E40: =E39/E37 -> 0.63701537 | F40: =F39/F37 -> 0.47941195 | G40: =G39/G37 -> 0.63730053 | H40: =H39/H37 -> 0.6140146 | I40: =I39/I37 -> 0.60611999 | J40: =J39/J37 -> 0.70096203 | ... L40: =L39/L37 -> 0.66616001
B41: Retention Ratio | C41: =1-C40 -> 0.57213779 | D41: =1-D40 -> 0.41192201 | E41: =1-E40 -> 0.36298463 | F41: =1-F40 -> 0.52058805 | G41: =1-G40 -> 0.36269947 | H41: =1-H40 -> 0.3859854 | I41: =1-I40 -> 0.39388001 | J41: =1-J40 -> 0.29903797 | ... L41: =1-L40 -> 0.33383999
A43: # | B43: Balance Sheet
B45: Equity Share Capital | C45: ='DATA Sheet'!B57 -> 1148 | D45: ='DATA Sheet'!C57 -> 1092 | E45: ='DATA Sheet'!D57 -> 2178 | F45: ='DATA Sheet'!E57 -> 2129 | G45: ='DATA Sheet'!F57 -> 2130 | H45: ='DATA Sheet'!G57 -> 2103 | I45: ='DATA Sheet'!H57 -> 2074 | J45: ='DATA Sheet'!I57 -> 2075 | ... L45: ='DATA Sheet'!K57 -> 2027
B46: Reserves | C46: ='DATA Sheet'!B58 -> 66869 | D46: ='DATA Sheet'!C58 -> 62410 | E46: ='DATA Sheet'!D58 -> 60533 | F46: ='DATA Sheet'!E58 -> 60105 | G46: ='DATA Sheet'!F58 -> 69401 | H46: ='DATA Sheet'!G58 -> 67203 | I46: ='DATA Sheet'!H58 -> 65671 | J46: ='DATA Sheet'!I58 -> 79101 | ... L46: ='DATA Sheet'!K58 -> 78847
B47: Borrowings | C47: ='DATA Sheet'!B59 -> 0 | D47: ='DATA Sheet'!C59 -> 0 | E47: ='DATA Sheet'!D59 -> 0 | F47: ='DATA Sheet'!E59 -> 3165 | G47: ='DATA Sheet'!F59 -> 3854 | H47: ='DATA Sheet'!G59 -> 3786 | I47: ='DATA Sheet'!H59 -> 4266 | J47: ='DATA Sheet'!I59 -> 3766 | ... L47: ='DATA Sheet'!K59 -> 3749
B48: Other Liabilities | C48: ='DATA Sheet'!B60 -> 11868 | D48: ='DATA Sheet'!C60 -> 11870 | E48: ='DATA Sheet'!D60 -> 15678 | F48: ='DATA Sheet'!E60 -> 15086 | G48: ='DATA Sheet'!F60 -> 18043 | H48: ='DATA Sheet'!G60 -> 25454 | I48: ='DATA Sheet'!H60 -> 28547 | J48: ='DATA Sheet'!I60 -> 30008 | ... L48: ='DATA Sheet'!K60 -> 41078
B50: Total Liablities | C50: =SUM(C45:C48) -> 79885 | D50: =SUM(D45:D48) -> 75372 | E50: =SUM(E45:E48) -> 78389 | F50: =SUM(F45:F48) -> 80485 | G50: =SUM(G45:G48) -> 93428 | H50: =SUM(H45:H48) -> 98546 | I50: =SUM(I45:I48) -> 100558 | J50: =SUM(J45:J48) -> 114950 | ... L50: =SUM(L45:L48) -> 125701
B53: Fixed Assets | C53: ='DATA Sheet'!B62 -> 8605 | D53: ='DATA Sheet'!C62 -> 9157 | E53: ='DATA Sheet'!D62 -> 10497 | F53: ='DATA Sheet'!E62 -> 13974 | G53: ='DATA Sheet'!F62 -> 14599 | H53: ='DATA Sheet'!G62 -> 14938 | I53: ='DATA Sheet'!H62 -> 15431 | J53: ='DATA Sheet'!I62 -> 14327 | ... L53: ='DATA Sheet'!K62 -> 13836
B54: Capital Work in Progress | C54: ='DATA Sheet'!B63 -> 1247 | D54: ='DATA Sheet'!C63 -> 1442 | E54: ='DATA Sheet'!D63 -> 1212 | F54: ='DATA Sheet'!E63 -> 945 | G54: ='DATA Sheet'!F63 -> 906 | H54: ='DATA Sheet'!G63 -> 411 | I54: ='DATA Sheet'!H63 -> 275 | J54: ='DATA Sheet'!I63 -> 277 | ... L54: ='DATA Sheet'!K63 -> 512
B55: Investments | C55: ='DATA Sheet'!B64 -> 24977 | D55: ='DATA Sheet'!C64 -> 17899 | E55: ='DATA Sheet'!D64 -> 18139 | F55: ='DATA Sheet'!E64 -> 17922 | G55: ='DATA Sheet'!F64 -> 24155 | H55: ='DATA Sheet'!G64 -> 28336 | I55: ='DATA Sheet'!H64 -> 28162 | J55: ='DATA Sheet'!I64 -> 34659 | ... L55: ='DATA Sheet'!K64 -> 38075
B57: Total Non Current Assets | C57: =SUM(C53:C55) -> 34829 | D57: =SUM(D53:D55) -> 28498 | E57: =SUM(E53:E55) -> 29848 | F57: =SUM(F53:F55) -> 32841 | G57: =SUM(G53:G55) -> 39660 | H57: =SUM(H53:H55) -> 43685 | I57: =SUM(I53:I55) -> 43868 | J57: =SUM(J53:J55) -> 49263 | ... L57: =SUM(L53:L55) -> 52423
B59: Trade receivables | C59: ='Balance sheet'!E13 -> 10960 | D59: ='Balance sheet'!F13 -> 12151 | E59: ='Balance sheet'!G13 -> 13370 | F59: ='Balance sheet'!H13 -> 15459 | G59: ='Balance sheet'!I13 -> 16394 | H59: ='Balance sheet'!J13 -> 18966 | I59: ='Balance sheet'!K13 -> 20773 | J59: ='Balance sheet'!L13 -> 25152 | ... L59: ='Balance sheet'!N13 -> 30337
B60: Cash Equivalents | C60: ='Balance sheet'!E14 -> 19153 | D60: ='Balance sheet'!F14 -> 16770 | E60: ='Balance sheet'!G14 -> 15551 | F60: ='Balance sheet'!H14 -> 13562 | G60: ='Balance sheet'!I14 -> 17612 | H60: ='Balance sheet'!J14 -> 12270 | I60: ='Balance sheet'!K14 -> 6534 | J60: ='Balance sheet'!L14 -> 8191 | ... L60: ='Balance sheet'!N14 -> 8727
B61: Loans and Advances | C61: ='Balance sheet'!E15 -> 715 | D61: ='Balance sheet'!F15 -> 760 | E61: ='Balance sheet'!G15 -> 1304 | F61: ='Balance sheet'!H15 -> 1069 | G61: ='Balance sheet'!I15 -> 1138 | H61: ='Balance sheet'!J15 -> 1576 | I61: ='Balance sheet'!K15 -> 2124 | J61: ='Balance sheet'!L15 -> 8748 | ... L61: ='Balance sheet'!N15 -> 5571
B62: Other asset items | C62: ='Balance sheet'!E16 -> 14228 | D62: ='Balance sheet'!F16 -> 17193 | E62: ='Balance sheet'!G16 -> 18316 | F62: ='Balance sheet'!H16 -> 17554 | G62: ='Balance sheet'!I16 -> 18624 | H62: ='Balance sheet'!J16 -> 22049 | I62: ='Balance sheet'!K16 -> 27259 | J62: ='Balance sheet'!L16 -> 23596 | ... L62: ='Balance sheet'!N16 -> 28643
B64: Total Current Assets | C64: =SUM(C59:C62) -> 45056 | D64: =SUM(D59:D62) -> 46874 | E64: =SUM(E59:E62) -> 48541 | F64: =SUM(F59:F62) -> 47644 | G64: =SUM(G59:G62) -> 53768 | H64: =SUM(H59:H62) -> 54861 | I64: =SUM(I59:I62) -> 56690 | J64: =SUM(J59:J62) -> 65687 | ... L64: =SUM(L59:L62) -> 73278
...

Sheet Ratio Analysis
B2: ='DATA Sheet'!B1&" Ratio Analysis" -> INFOSYS LTD Ratio Analysis
B3: Years | C3: FY17 | D3: FY18 | E3: FY19 | F3: FY20 | G3: FY21 | H3: FY22 | I3: FY23 | J3: FY24 | K3: FY25 | L3: FY26
A4: #
B5: Sales Growth | D5: ='Historical FS'!D6 -> 0.044730051 | E5: ='Historical FS'!E6 -> 0.18026832 | F5: ='Historical FS'!F6 -> 0.081250769 | G5: ='Historical FS'!G6 -> 0.086847066 | H5: ='Historical FS'!H6 -> 0.20984263 | I5: ='Historical FS'!I6 -> 0.19313065 | J5: ='Historical FS'!J6 -> 0.039664877 | K5: ='Historical FS'!K6 -> 0.059402946 | L5: ='Historical FS'!L6 -> 0.089514759
B6: EBITDA Growth | D6: ='Historical FS'!D18/'Historical FS'!C18-1 -> 0.0052304295 | E6: ='Historical FS'!E18/'Historical FS'!D18-1 -> 0.079609181 | F6: ='Historical FS'!F18/'Historical FS'!E18-1 -> 0.072882082 | G6: ='Historical FS'!G18/'Historical FS'!F18-1 -> 0.22071375 | H6: ='Historical FS'!H18/'Historical FS'!G18-1 -> 0.13783375 | I6: ='Historical FS'!I18/'Historical FS'!H18-1 -> 0.10298979 | J6: ='Historical FS'!J18/'Historical FS'!I18-1 -> 0.034632176 | K6: ='Historical FS'!K18/'Historical FS'!J18-1 -> 0.054854048 | L6: ='Historical FS'!L18/'Historical FS'!K18-1 -> 0.075047016
B7: PBT Growth | D7: ='Historical FS'!D31/'Historical FS'!C31-1 -> 0.05121977 | E7: ='Historical FS'!E31/'Historical FS'!D31-1 -> 0.00095439019 | F7: ='Historical FS'!F31/'Historical FS'!E31-1 -> 0.027600743 | G7: ='Historical FS'!G31/'Historical FS'!F31-1 -> 0.19534111 | H7: ='Historical FS'!H31/'Historical FS'!G31-1 -> 0.1641541 | I7: ='Historical FS'!I31/'Historical FS'!H31-1 -> 0.11047552 | J7: ='Historical FS'!J31/'Historical FS'!I31-1 -> 0.13620706 | K7: ='Historical FS'!K31/'Historical FS'!J31-1 -> -0.014240814 | L7: ='Historical FS'!L31/'Historical FS'!K31-1 -> 0.093563951
B8: Net profit Growth | D8: ='Historical FS'!D37/'Historical FS'!C37-1 -> 0.16912723 | E8: ='Historical FS'!E37/'Historical FS'!D37-1 -> -0.089941195 | F8: ='Historical FS'!F37/'Historical FS'!E37-1 -> 0.057203102 | G8: ='Historical FS'!G37/'Historical FS'!F37-1 -> 0.1611658 | H8: ='Historical FS'!H37/'Historical FS'!G37-1 -> 0.17658466 | I8: ='Historical FS'!I37/'Historical FS'!H37-1 -> 0.095738168 | J8: ='Historical FS'!J37/'Historical FS'!I37-1 -> 0.17044868 | K8: ='Historical FS'!K37/'Historical FS'!J37-1 -> -0.061173533 | L8: ='Historical FS'!L37/'Historical FS'!K37-1 -> 0.14248279
A11: # | B11: Gross Margin | C11: ='Historical FS'!C12 -> 0.35433217 | D11: ='Historical FS'!D12 -> 0.34888039 | E11: ='Historical FS'!E12 -> 0.33180133 | F11: ='Historical FS'!F12 -> 0.31701393 | G11: ='Historical FS'!G12 -> 0.32528634 | H11: ='Historical FS'!H12 -> 0.30810083 | I11: ='Historical FS'!I12 -> 0.28870128 | J11: ='Historical FS'!J12 -> 0.2877541 | ... L11: ='Historical FS'!L12 -> 0.28581028
B12: EBITDA Margin | C12: ='Historical FS'!C19 -> 0.29022247 | D12: ='Historical FS'!D19 -> 0.27924961 | E12: ='Historical FS'!E19 -> 0.25543382 | F12: ='Historical FS'!F19 -> 0.2534568 | G12: ='Historical FS'!G19 -> 0.28467502 | H12: ='Historical FS'!H19 -> 0.26773138 | I12: ='Historical FS'!I19 -> 0.24750431 | J12: ='Historical FS'!J19 -> 0.24630622 | ... L12: ='Historical FS'!L19 -> 0.24199195
B13: PBT Margin | C13: ='Historical FS'!C32 -> 0.31941844 | D13: ='Historical FS'!D32 -> 0.32140263 | E13: ='Historical FS'!E32 -> 0.27257308 | F13: ='Historical FS'!F32 -> 0.25904841 | G13: ='Historical FS'!G32 -> 0.28490781 | H13: ='Historical FS'!H32 -> 0.27414855 | I13: ='Historical FS'!I32 -> 0.25515668 | J13: ='Historical FS'!J32 -> 0.27885026 | ... L13: ='Historical FS'!L32 -> 0.26043046
B14: Net Margin | C14: ='Historical FS'!C37/'Historical FS'!C5 -> 0.23306178 | D14: ='Historical FS'!D37/'Historical FS'!D5 -> 0.26081271 | E14: ='Historical FS'!E37/'Historical FS'!E5 -> 0.20110249 | F14: ='Historical FS'!F37/'Historical FS'!F5 -> 0.19662985 | G14: ='Historical FS'!G37/'Historical FS'!G5 -> 0.21007543 | H14: ='Historical FS'!H37/'Historical FS'!H5 -> 0.20430056 | I14: ='Historical FS'!I37/'Historical FS'!I5 -> 0.18762398 | J14: ='Historical FS'!J37/'Historical FS'!J5 -> 0.21122599 | ... L14: ='Historical FS'!L37/'Historical FS'!L5 -> 0.19628542
A17: # | B17: Sales Expenses as a % of sales | C17: ='Historical FS'!C16 -> 0.0641097 | D17: ='Historical FS'!D16 -> 0.069630778 | E17: ='Historical FS'!E16 -> 0.076367516 | F17: ='Historical FS'!F16 -> 0.063557124 | G17: ='Historical FS'!G16 -> 0.040611323 | H17: ='Historical FS'!H16 -> 0.040369444 | I17: ='Historical FS'!I16 -> 0.041196962 | J17: ='Historical FS'!J16 -> 0.041447884 | ... L17: ='Historical FS'!L16 -> 0.04381833
B18: Depreciation as a % of sales | C18: ='Historical FS'!C25/'Historical FS'!C5 -> 0.022449358 | D18: ='Historical FS'!D25/'Historical FS'!D5 -> 0.022731309 | E18: ='Historical FS'!E25/'Historical FS'!E5 -> 0.021872051 | F18: ='Historical FS'!F25/'Historical FS'!F5 -> 0.027123104 | G18: ='Historical FS'!G25/'Historical FS'!G5 -> 0.027016016 | H18: ='Historical FS'!H25/'Historical FS'!H5 -> 0.023369251 | I18: ='Historical FS'!I25/'Historical FS'!I5 -> 0.022199107 | J18: ='Historical FS'!J25/'Historical FS'!J5 -> 0.022833565 | ... L18: ='Historical FS'!L25/'Historical FS'!L5 -> 0.016086656
B19: Operating income as a % of sales | C19: ='Historical FS'!C19 -> 0.29022247 | D19: ='Historical FS'!D19 -> 0.27924961 | E19: ='Historical FS'!E19 -> 0.25543382 | F19: ='Historical FS'!F19 -> 0.2534568 | G19: ='Historical FS'!G19 -> 0.28467502 | H19: ='Historical FS'!H19 -> 0.26773138 | I19: ='Historical FS'!I19 -> 0.24750431 | J19: ='Historical FS'!J19 -> 0.24630622 | ... L19: ='Historical FS'!L19 -> 0.24199195
B22: EBIT | C22: ='Historical FS'!C18-'Historical FS'!C25+'Historical FS'!C28 -> 18938 | D22: ='Historical FS'!D18-'Historical FS'!D25+'Historical FS'!D28 -> 19908 | E22: ='Historical FS'!E18-'Historical FS'!E25+'Historical FS'!E28 -> 19927 | F22: ='Historical FS'!F18-'Historical FS'!F25+'Historical FS'!F28 -> 20591 | G22: ='Historical FS'!G18-'Historical FS'!G25+'Historical FS'!G28 -> 24603 | H22: ='Historical FS'!H18-'Historical FS'!H25+'Historical FS'!H28 -> 28623 | I22: ='Historical FS'!I18-'Historical FS'!I25+'Historical FS'!I28 -> 31800 | J22: ='Historical FS'!J18-'Historical FS'!J25+'Historical FS'!J28 -> 36230 | ... L22: ='Historical FS'!L18-'Historical FS'!L25+'Historical FS'!L28 -> 38964
B23: Equity and debt | C23: =SUM('Historical FS'!C45:C47) -> 68017 | D23: =SUM('Historical FS'!D45:D47) -> 63502 | E23: =SUM('Historical FS'!E45:E47) -> 62711 | F23: =SUM('Historical FS'!F45:F47) -> 65399 | G23: =SUM('Historical FS'!G45:G47) -> 75385 | H23: =SUM('Historical FS'!H45:H47) -> 73092 | I23: =SUM('Historical FS'!I45:I47) -> 72011 | J23: =SUM('Historical FS'!J45:J47) -> 84942 | ... L23: =SUM('Historical FS'!L45:L47) -> 84623
A24: # | B24: Return on Capital employed | C24: =C22/C23 -> 0.27843039 | D24: =D22/D23 -> 0.31350194 | E24: =E22/E23 -> 0.31775924 | F24: =F22/F23 -> 0.31485191 | G24: =G22/G23 -> 0.32636466 | H24: =H22/H23 -> 0.39160236 | I24: =I22/I23 -> 0.4415992 | J24: =J22/J23 -> 0.42652634 | ... L24: =L22/L23 -> 0.4604422
B25: Retained Earnings | C25: ='Historical FS'!C41 -> 0.57213779 | D25: ='Historical FS'!D41 -> 0.41192201 | E25: ='Historical FS'!E41 -> 0.36298463 | F25: ='Historical FS'!F41 -> 0.52058805 | G25: ='Historical FS'!G41 -> 0.36269947 | H25: ='Historical FS'!H41 -> 0.3859854 | I25: ='Historical FS'!I41 -> 0.39388001 | J25: ='Historical FS'!J41 -> 0.29903797 | ... L25: ='Historical FS'!L41 -> 0.33383999
B26: ROE | C26: ='Historical FS'!C37/(SUM('Historical FS'!C45:C46)) -> 0.20315509 | D26: ='Historical FS'!D37/(SUM('Historical FS'!D45:D46)) -> 0.25440144 | E26: ='Historical FS'!E37/(SUM('Historical FS'!E45:E46)) -> 0.23444053 | F26: ='Historical FS'!F37/(SUM('Historical FS'!F45:F46)) -> 0.24975094 | G26: ='Historical FS'!G37/(SUM('Historical FS'!G45:G46)) -> 0.25231019 | H26: ='Historical FS'!H37/(SUM('Historical FS'!H45:H46)) -> 0.30639483 | I26: ='Historical FS'!I37/(SUM('Historical FS'!I45:I46)) -> 0.34346446 | J26: ='Historical FS'!J37/(SUM('Historical FS'!J45:J46)) -> 0.33549325 | ... L26: ='Historical FS'!L37/(SUM('Historical FS'!L45:L46)) -> 0.36119148
B27: Sustainable Growth rate | C27: =C25*C26 -> 0.11623271 | D27: =D25*D26 -> 0.10479355 | E27: =E25*E26 -> 0.085098308 | F27: =F25*F26 -> 0.13001735 | G27: =G25*G26 -> 0.091512771 | H27: =H25*H26 -> 0.11826393 | I27: =I25*I26 -> 0.13528378 | J27: =J25*J26 -> 0.10032522 | ... L27: =L25*L26 -> 0.12058016
B28: Interest Coverage ratio | C28: =IFERROR('Ratio Analysis'!C22/'Historical FS'!C22,"N.A") -> N.A | D28: =IFERROR('Ratio Analysis'!D22/'Historical FS'!D22,"N.A") -> N.A | E28: =IFERROR('Ratio Analysis'!E22/'Historical FS'!E22,"N.A") -> N.A | F28: =IFERROR('Ratio Analysis'!F22/'Historical FS'!F22,"N.A") -> 180.62281 | G28: =IFERROR('Ratio Analysis'!G22/'Historical FS'!G22,"N.A") -> 195.2619 | H28: =IFERROR('Ratio Analysis'!H22/'Historical FS'!H22,"N.A") -> 223.61719 | I28: =IFERROR('Ratio Analysis'!I22/'Historical FS'!I22,"N.A") -> 202.54777 | J28: =IFERROR('Ratio Analysis'!J22/'Historical FS'!J22,"N.A") -> 130.79422 | ... L28: =IFERROR('Ratio Analysis'!L22/'Historical FS'!L22,"N.A") -> 188.23188
A31: # | B31: Debtor Turnover Ratio | C31: ='Historical FS'!C5/'Historical FS'!C59 -> 5.4095803 | D31: ='Historical FS'!D5/'Historical FS'!D59 -> 5.0976051 | E31: ='Historical FS'!E5/'Historical FS'!E59 -> 5.467988 | F31: ='Historical FS'!F5/'Historical FS'!F59 -> 5.113332 | G31: ='Historical FS'!G5/'Historical FS'!G59 -> 5.2404538 | H31: ='Historical FS'!H5/'Historical FS'!H59 -> 5.4803332 | I31: ='Historical FS'!I5/'Historical FS'!I59 -> 5.969961 | J31: ='Historical FS'!J5/'Historical FS'!J59 -> 5.126153 | ... L31: ='Historical FS'!L5/'Historical FS'!L59 -> 4.9055279
B32: Creditor Turnover Ratio | C32: ='Historical FS'!C8/'Balance sheet'!C19 -> 308.71774 | D32: ='Historical FS'!D8/'Balance sheet'!D19 -> 64.736758 | E32: ='Historical FS'!E8/'Balance sheet'!E19 -> 181.59851 | F32: ='Historical FS'!F8/'Balance sheet'!F19 -> 73.154472 | G32: ='Historical FS'!G8/'Balance sheet'!G19 -> 36.138404 | H32: ='Historical FS'!H8/'Balance sheet'!H19 -> 47.034663 | I32: ='Historical FS'!I8/'Balance sheet'!I19 -> 56.473111 | J32: ='Historical FS'!J8/'Balance sheet'!J19 -> 34.406894 | ... L32: ='Historical FS'!L8/'Balance sheet'!L19 -> 42.633373
B33: Inventory Turnover Ratio
B34: Fixed Assets Turnover Ratio | C34: ='Historical FS'!C5/'Historical FS'!C53 -> 6.8900639 | D34: ='Historical FS'!D5/'Historical FS'!D53 -> 6.7643333 | E34: ='Historical FS'!E5/'Historical FS'!E53 -> 6.9645613 | F34: ='Historical FS'!F5/'Historical FS'!F53 -> 5.6567196 | G34: ='Historical FS'!G5/'Historical FS'!G53 -> 5.8847866 | H34: ='Historical FS'!H5/'Historical FS'!H53 -> 6.9580935 | I34: ='Historical FS'!I5/'Historical FS'!I53 -> 8.0366794 | J34: ='Historical FS'!J5/'Historical FS'!J53 -> 8.999302 | ... L34: ='Historical FS'!L5/'Historical FS'!L53 -> 10.755927
A37: # | B37: DAYS ( Assuming 360 days)
B38: Debtor | C38: =360/C31 -> 66.548601 | D38: =360/D31 -> 70.621398 | E38: =360/E31 -> 65.837745 | F38: =360/F31 -> 70.40419 | G38: =360/G31 -> 68.69634 | H38: =360/H31 -> 65.689436 | I38: =360/I31 -> 60.301901 | J38: =360/J31 -> 70.228103 | ... L38: =360/L31 -> 73.386597
B39: Creditors | C39: =360/C32 -> 1.1661137 | D39: =360/D32 -> 5.5609829 | E39: =360/E32 -> 1.9823951 | F39: =360/F32 -> 4.9210936 | G39: =360/G32 -> 9.9617017 | H39: =360/H32 -> 7.6539296 | I39: =360/I32 -> 6.3747152 | J39: =360/J32 -> 10.463019 | ... L39: =360/L32 -> 8.444089
B40: Inventory
B41: Cash Conversion Cycle
A44: # | B44: CFO/Sales | C44: ='Historical FS'!C74/'Historical FS'!C5 -> 0.17672755 | D44: ='Historical FS'!D74/'Historical FS'!D5 -> 0.20140133 | E44: ='Historical FS'!E74/'Historical FS'!E5 -> 0.19134967 | F44: ='Historical FS'!F74/'Historical FS'!F5 -> 0.19699672 | G44: ='Historical FS'!G74/'Historical FS'!G5 -> 0.23165565 | H44: ='Historical FS'!H74/'Historical FS'!H5 -> 0.21258418 | I44: ='Historical FS'!I74/'Historical FS'!I5 -> 0.15457126 | J44: ='Historical FS'!J74/'Historical FS'!J5 -> 0.16122327 | ... L44: ='Historical FS'!L74/'Historical FS'!L5 -> 0.18925003
B45: CFO/Total Assets | C45: ='Historical FS'!C74/'Historical FS'!C66 -> 0.13116355 | D45: ='Historical FS'!D74/'Historical FS'!D66 -> 0.16551239 | E45: ='Historical FS'!E74/'Historical FS'!E66 -> 0.17845616 | F45: ='Historical FS'!F74/'Historical FS'!F66 -> 0.19347705 | G45: ='Historical FS'!G74/'Historical FS'!G66 -> 0.21301965 | H45: ='Historical FS'!H74/'Historical FS'!H66 -> 0.22422016 | I45: ='Historical FS'!I74/'Historical FS'!I66 -> 0.19062631 | J45: ='Historical FS'!J74/'Historical FS'!J66 -> 0.18083515 | ... L45: ='Historical FS'!L74/'Historical FS'!L66 -> 0.2240555
B46: CFO/Debt | C46: =IFERROR('Historical FS'!C74/'Historical FS'!C47,"N.A") -> N.A | D46: =IFERROR('Historical FS'!D74/'Historical FS'!D47,"N.A") -> N.A | E46: =IFERROR('Historical FS'!E74/'Historical FS'!E47,"N.A") -> N.A | F46: =IFERROR('Historical FS'!F74/'Historical FS'!F47,"N.A") -> 4.9200632 | G46: =IFERROR('Historical FS'!G74/'Historical FS'!G47,"N.A") -> 5.1639855 | H46: =IFERROR('Historical FS'!H74/'Historical FS'!H47,"N.A") -> 5.8362388 | I46: =IFERROR('Historical FS'!I74/'Historical FS'!I47,"N.A") -> 4.4934365 | J46: =IFERROR('Historical FS'!J74/'Historical FS'!J47,"N.A") -> 5.5196495 | ... L46: =IFERROR('Historical FS'!L74/'Historical FS'!L47,"N.A") -> 7.5124033

Sheet Dupont
B2: ='DATA Sheet'!B1&" Dupont" -> INFOSYS LTD Dupont
B3: Years | C3: FY17 | D3: FY18 | E3: FY19 | F3: FY20 | G3: FY21 | H3: FY22 | I3: FY23 | J3: FY24 | K3: FY25 | L3: FY26
B4: Net margin | C4: ='Ratio Analysis'!C14 -> 0.23306178 | D4: ='Ratio Analysis'!D14 -> 0.26081271 | E4: ='Ratio Analysis'!E14 -> 0.20110249 | F4: ='Ratio Analysis'!F14 -> 0.19662985 | G4: ='Ratio Analysis'!G14 -> 0.21007543 | H4: ='Ratio Analysis'!H14 -> 0.20430056 | I4: ='Ratio Analysis'!I14 -> 0.18762398 | J4: ='Ratio Analysis'!J14 -> 0.21122599 | ... L4: ='Ratio Analysis'!L14 -> 0.19628542
B5: Asset turnover | C5: ='Historical FS'!C5/'Historical FS'!C66 -> 0.74217938 | D5: ='Historical FS'!D5/'Historical FS'!D66 -> 0.82180385 | E5: ='Historical FS'!E5/'Historical FS'!E66 -> 0.9326181 | F5: ='Historical FS'!F5/'Historical FS'!F66 -> 0.98213332 | G5: ='Historical FS'!G5/'Historical FS'!G66 -> 0.91955302 | H5: ='Historical FS'!H5/'Historical FS'!H66 -> 1.0547359 | I5: ='Historical FS'!I5/'Historical FS'!I66 -> 1.2332584 | J5: ='Historical FS'!J5/'Historical FS'!J66 -> 1.1216442 | ... L5: ='Historical FS'!L5/'Historical FS'!L66 -> 1.1839126
B6: Fin Lev | C6: ='Historical FS'!C66/SUM('Historical FS'!C45:C46) -> 1.1744858 | D6: ='Historical FS'!D66/SUM('Historical FS'!D45:D46) -> 1.1869232 | E6: ='Historical FS'!E66/SUM('Historical FS'!E45:E46) -> 1.250004 | F6: ='Historical FS'!F66/SUM('Historical FS'!F45:F46) -> 1.2932641 | G6: ='Historical FS'!G66/SUM('Historical FS'!G45:G46) -> 1.306119 | H6: ='Historical FS'!H66/SUM('Historical FS'!H45:H46) -> 1.4218971 | I6: ='Historical FS'!I66/SUM('Historical FS'!I45:I46) -> 1.4843605 | J6: ='Historical FS'!J66/SUM('Historical FS'!J45:J46) -> 1.4160589 | ... L6: ='Historical FS'!L66/SUM('Historical FS'!L45:L46) -> 1.554282
B8: ROE | C8: =PRODUCT(C4:C6) -> 0.20315509 | D8: =PRODUCT(D4:D6) -> 0.25440144 | E8: =PRODUCT(E4:E6) -> 0.23444053 | F8: =PRODUCT(F4:F6) -> 0.24975094 | G8: =PRODUCT(G4:G6) -> 0.25231019 | H8: =PRODUCT(H4:H6) -> 0.30639483 | I8: =PRODUCT(I4:I6) -> 0.34346446 | J8: =PRODUCT(J4:J6) -> 0.33549325 | ... L8: =PRODUCT(L4:L6) -> 0.36119148

Sheet KPIs
B2: ='DATA Sheet'!B1&" KPIs" -> INFOSYS LTD KPIs
B3: Years | C3: FY16 | D3: FY17 | E3: FY18 | F3: FY19 | G3: FY20 | H3: FY21 | I3: FY22 | J3: FY23 | K3: FY24 | L3: FY25 | M3: FY26
B4: Active Clients | C4: 1092 | D4: 1162 | E4: 1204 | F4: 1279 | G4: 1411 | H4: 1626 | I4: 1741 | J4: 1872 | K4: 1882 | L4: 1869 | M4: 1965
B5: Mega Clients ($100M+ revenue) | C5: 14 | D5: 19 | E5: 20 | F5: 25 | G5: 28 | H5: 32 | I5: 38 | J5: 40 | K5: 40 | L5: 42 | M5: 45
B6: Total Headcount | C6: 194044 | D6: 200364 | E6: 204107 | F6: 228123 | G6: 242371 | H6: 259619 | I6: 314015 | J6: 343234 | K6: 317240 | L6: 323578 | M6: 328594
B7: Large Deal Total Contract Value (TCV)(USD Bn) | C7: 2.8 | D7: 3.5 | F7: 6.3 | G7: 9 | H7: 14 | I7: 9.5 | J7: 9.8 | K7: 17.7 | L7: 11.6 | M7: 14.9
B8: Voluntary Attrition (LTM, IT Services)% | C8: 13.6 | D8: 15 | E8: 16.4 | G8: 17.4 | H8: 10.9 | I8: 27.7 | J8: 20.9 | K8: 12.6 | L8: 14.1 | M8: 12.6
B9: Large Clients ($50M+ revenue) | D9: 56 | E9: 57 | F9: 60 | J9: 75 | K9: 83 | L9: 85 | M9: 88
B10: Freshers Hired | H10: 19000 | I10: 60405 | J10: 50000 | K10: 11900 | L10: 15288 | M10: 20000
B11: Utilization (Excluding Trainees) % | C11: 80.8 | D11: 81.7 | E11: 84.6 | F11: 84.3 | G11: 84 | M11: 84.4
B12: Onsite Mix | D12: 53.7 | E12: 55.4 | F12: 54.9 | G12: 54.8
B13: R&D Expenditure (Percentage of Turnover) | C13: 0.8 | D13: 0.6 | E13: 0.6 | F13: 0.6 | G13: 0.6 | H13: 0.6 | I13: 0.5 | J13: 0.5 | K13: 0.54 | L13: 0.62
B16: Sales per Client for FY16 | C16: ='P&L'!D4/KPIs!C4 -> 49.434982
B17: Avg employee cost | C17: =0.5227*'P&L'!D5 -> 20005.82 | D17: =C17/C6 -> 0.1030994

Sheet Scenarios>>

Sheet Scenarios
D5: Particulars | E5: Pessmistic | F5: Base | G5: Optmistic | H5: Choose
D6: GDP growth | E6: -0.02 | F6: 0 | G6: 0.02 | H6: =INDEX($E6:$G6,MATCH(DASHBOARD!$D$2,Scenarios!$E$5:$G$5,0)) -> 0
D7: Headcount | E7: -0.02 | F7: 0 | G7: 0.01 | H7: =INDEX($E7:$G7,MATCH(DASHBOARD!$D$2,Scenarios!$E$5:$G$5,0)) -> 0
D8: Avg Employee cost | E8: 0.02 | F8: 0 | G8: -0.02 | H8: =INDEX($E8:$G8,MATCH(DASHBOARD!$D$2,Scenarios!$E$5:$G$5,0)) -> 0
D9: Active Clients | E9: -0.03 | F9: 0 | G9: 0.02 | H9: =INDEX($E9:$G9,MATCH(DASHBOARD!$D$2,Scenarios!$E$5:$G$5,0)) -> 0
D10: Sales Per client | E10: -0.015 | F10: 0 | G10: 0.02 | H10: =INDEX($E10:$G10,MATCH(DASHBOARD!$D$2,Scenarios!$E$5:$G$5,0)) -> 0
D11: Large clients | E11: -0.015 | F11: 0 | G11: 0.015 | H11: =INDEX($E11:$G11,MATCH(DASHBOARD!$D$2,Scenarios!$E$5:$G$5,0)) -> 0
D12: Other Clients | E12: -0.015 | F12: 0 | G12: 0.015 | H12: =INDEX($E12:$G12,MATCH(DASHBOARD!$D$2,Scenarios!$E$5:$G$5,0)) -> 0

Sheet Forecast>>

Sheet Forecast Drivers
B2: ='DATA Sheet'!B1&" Forecast Assumptions" -> INFOSYS LTD Forecast Assumptions
B3: Year Weights | C3: 1 | D3: =C3+1 -> 2 | E3: =D3+1 -> 3 | F3: =E3+1 -> 4 | G3: =F3+1 -> 5 | H3: =G3+1 -> 6 | I3: =H3+1 -> 7 | J3: =I3+1 -> 8 | K3: =J3+1 -> 9 | ... Q3: =P3+1 -> 15
B4: Years (As on March) | C4: 2017 | D4: =C4+1 -> 2018 | E4: =D4+1 -> 2019 | F4: =E4+1 -> 2020 | G4: =F4+1 -> 2021 | H4: =G4+1 -> 2022 | I4: =H4+1 -> 2023 | J4: =I4+1 -> 2024 | K4: =J4+1 -> 2025 | ... Q4: =P4+1 -> 2031
A6: # | B6: Revenue Drivers
B7: Sales | C7: ='Historical FS'!C5 -> 59289 | D7: ='Historical FS'!D5 -> 61941 | E7: ='Historical FS'!E5 -> 73107 | F7: ='Historical FS'!F5 -> 79047 | G7: ='Historical FS'!G5 -> 85912 | H7: ='Historical FS'!H5 -> 103940 | I7: ='Historical FS'!I5 -> 124014 | J7: ='Historical FS'!J5 -> 128933 | ... L7: ='Historical FS'!L5 -> 148819 | M7: =M12*M9 -> 160489.88 | N7: =N12*N9 -> 173076.03 | O7: =O12*O9 -> 186649.22 | P7: =P12*P9 -> 201286.87 | Q7: =Q12*Q9 -> 217072.46
B9: Active Clients | C9: =KPIs!D4 -> 1162 | D9: =KPIs!E4 -> 1204 | E9: =KPIs!F4 -> 1279 | F9: =KPIs!G4 -> 1411 | G9: =KPIs!H4 -> 1626 | H9: =KPIs!I4 -> 1741 | I9: =KPIs!J4 -> 1872 | J9: =KPIs!K4 -> 1882 | ... L9: =KPIs!M4 -> 1965 | M9: =L9*(1+M10) -> 2026.4273 | N9: =M9*(1+N10) -> 2089.7748 | O9: =N9*(1+O10) -> 2155.1027 | P9: =O9*(1+P10) -> 2222.4727 | Q9: =P9*(1+Q10) -> 2291.9487
B10: % growth | C10: =C9/KPIs!C4-1 -> 0.064102564 | D10: =D9/C9-1 -> 0.036144578 | E10: =E9/D9-1 -> 0.062292359 | F10: =F9/E9-1 -> 0.10320563 | G10: =G9/F9-1 -> 0.1523742 | H10: =H9/G9-1 -> 0.070725707 | I10: =I9/H9-1 -> 0.075244113 | J10: =J9/I9-1 -> 0.0053418803 | K10: =K9/J9-1 -> -0.0069075452 | L10: =L9/K9-1 -> 0.051364366 | M10: =AVERAGE($I10:$L10)+Scenarios!$H$9 -> 0.031260703 | N10: =AVERAGE($I10:$L10)+Scenarios!$H$9 -> 0.031260703 | O10: =AVERAGE($I10:$L10)+Scenarios!$H$9 -> 0.031260703 | P10: =AVERAGE($I10:$L10)+Scenarios!$H$9 -> 0.031260703 | Q10: =AVERAGE($I10:$L10)+Scenarios!$H$9 -> 0.031260703
B12: sales per Client | C12: =C7/C9 -> 51.023236 | D12: =D7/D9 -> 51.446013 | E12: =E7/E9 -> 57.1595 | F12: =F7/F9 -> 56.02197 | G12: =G7/G9 -> 52.836408 | H12: =H7/H9 -> 59.701321 | I12: =I7/I9 -> 66.246795 | J12: =J7/J9 -> 68.508502 | ... L12: =L7/L9 -> 75.73486 | M12: =L12*(1+M13) -> 79.19844 | N12: =M12*(1+N13) -> 82.820419 | O12: =N12*(1+O13) -> 86.608043 | P12: =O12*(1+P13) -> 90.568885 | Q12: =P12*(1+Q13) -> 94.710869
B13: Growth | C13: =C12/KPIs!C16-1 -> 0.032128142 | D13: =D12/C12-1 -> 0.0082859796 | E13: =E12/D12-1 -> 0.1110579 | F13: =F12/E12-1 -> -0.019900968 | G13: =G12/F12-1 -> -0.056862725 | H13: =H12/G12-1 -> 0.12992769 | I13: =I12/H12-1 -> 0.109637 | J13: =J12/I12-1 -> 0.034140621 | K13: =K12/J12-1 -> 0.06677172 | L13: =L12/K12-1 -> 0.036286557 | M13: =AVERAGE($J13:$L13)+Scenarios!$H$10 -> 0.045732966 | N13: =AVERAGE($J13:$L13)+Scenarios!$H$10 -> 0.045732966 | O13: =AVERAGE($J13:$L13)+Scenarios!$H$10 -> 0.045732966 | P13: =AVERAGE($J13:$L13)+Scenarios!$H$10 -> 0.045732966 | Q13: =AVERAGE($J13:$L13)+Scenarios!$H$10 -> 0.045732966
B16: Large and Mega Client | C16: =KPIs!D5+KPIs!D9 -> 75 | D16: =KPIs!E5+KPIs!E9 -> 77 | E16: =KPIs!F5+KPIs!F9 -> 85 | F16: =KPIs!G5+KPIs!G9 -> 28 | G16: =KPIs!H5+KPIs!H9 -> 32 | H16: =KPIs!I5+KPIs!I9 -> 38 | I16: =KPIs!J5+KPIs!J9 -> 115 | J16: =KPIs!K5+KPIs!K9 -> 123 | ... L16: =KPIs!M5+KPIs!M9 -> 133 | M16: =L16*(1+M17) -> 139.62028 | N16: =M16*(1+N17) -> 146.5701 | O16: =N16*(1+O17) -> 153.86585 | P16: =O16*(1+P17) -> 161.52476 | Q16: =P16*(1+Q17) -> 169.5649
B17: Growth | C17: =C16/(KPIs!C5+KPIs!C9) -> 5.3571429 | D17: =D16/C16-1 -> 0.026666667 | E17: =E16/D16-1 -> 0.1038961 | F17: =F16/E16-1 -> -0.67058824 | G17: =G16/F16-1 -> 0.14285714 | H17: =H16/G16-1 -> 0.1875 | I17: =I16/H16-1 -> 2.0263158 | J17: =J16/I16-1 -> 0.069565217 | K17: =K16/J16-1 -> 0.032520325 | L17: =L16/K16-1 -> 0.047244094 | M17: =AVERAGE($J17:$L17)+Scenarios!$H$11 -> 0.049776546 | N17: =AVERAGE($J17:$L17)+Scenarios!$H$11 -> 0.049776546 | O17: =AVERAGE($J17:$L17)+Scenarios!$H$11 -> 0.049776546 | P17: =AVERAGE($J17:$L17)+Scenarios!$H$11 -> 0.049776546 | Q17: =AVERAGE($J17:$L17)+Scenarios!$H$11 -> 0.049776546
B19: % of total client | C19: =C16/C9 -> 0.06454389 | D19: =D16/D9 -> 0.063953488 | E19: =E16/E9 -> 0.06645817 | F19: =F16/F9 -> 0.019844082 | G19: =G16/G9 -> 0.019680197 | H19: =H16/H9 -> 0.021826536 | I19: =I16/I9 -> 0.061431624 | J19: =J16/J9 -> 0.065356004 | ... L19: =L16/L9 -> 0.067684478 | M19: =AVERAGE($J19:$L19) -> 0.066997086 | N19: =AVERAGE($J19:$L19) -> 0.066997086 | O19: =AVERAGE($J19:$L19) -> 0.066997086 | P19: =AVERAGE($J19:$L19) -> 0.066997086 | Q19: =AVERAGE($J19:$L19) -> 0.066997086
B20: Large & mega Sales | C20: =C19*C7 -> 3826.7427 | D20: =D19*D7 -> 3961.343 | E20: =E19*E7 -> 4858.5575 | F20: =F19*F7 -> 1568.6152 | G20: =G19*G7 -> 1690.7651 | H20: =H19*H7 -> 2268.6502 | I20: =I19*I7 -> 7618.3814 | J20: =J19*J7 -> 8426.5457 | ... Q20: =Q19*Q7 -> 14543.222
B23: Other Client | C23: =C9-C16 -> 1087 | D23: =D9-D16 -> 1127 | E23: =E9-E16 -> 1194 | F23: =F9-F16 -> 1383 | G23: =G9-G16 -> 1594 | H23: =H9-H16 -> 1703 | I23: =I9-I16 -> 1757 | J23: =J9-J16 -> 1759 | ... L23: =L9-L16 -> 1832 | M23: =L23*(1+M24) -> 1926.6498 | N23: =M23*(1+N24) -> 2026.1897 | O23: =N23*(1+O24) -> 2130.8723 | P23: =O23*(1+P24) -> 2240.9633 | Q23: =P23*(1+Q24) -> 2356.7421
B24: Growth | C24: =C23/(KPIs!C4-KPIs!C5-KPIs!C9)-1 -> 0.0083487941 | D24: =D23/C23-1 -> 0.036798528 | E24: =E23/D23-1 -> 0.059449867 | F24: =F23/E23-1 -> 0.15829146 | G24: =G23/F23-1 -> 0.15256688 | H24: =H23/G23-1 -> 0.06838143 | I24: =I23/H23-1 -> 0.031708749 | J24: =J23/I23-1 -> 0.0011383039 | K24: =K23/J23-1 -> -0.0096645821 | L24: =L23/K23-1 -> 0.051664753 | M24: =L24+Scenarios!$H$12 -> 0.051664753 | N24: =M24+Scenarios!$H$12 -> 0.051664753 | O24: =N24+Scenarios!$H$12 -> 0.051664753 | P24: =O24+Scenarios!$H$12 -> 0.051664753 | Q24: =P24+Scenarios!$H$12 -> 0.051664753
B26: % of total client | C26: =1-C19 -> 0.93545611 | D26: =1-D19 -> 0.93604651 | E26: =1-E19 -> 0.93354183 | F26: =1-F19 -> 0.98015592 | G26: =1-G19 -> 0.9803198 | H26: =1-H19 -> 0.97817346 | I26: =1-I19 -> 0.93856838 | J26: =1-J19 -> 0.934644 | ... Q26: =1-Q19 -> 0.93300291
B27: Other Client sales | C27: =C26*C7 -> 55462.257 | D27: =D26*D7 -> 57979.657 | E27: =E26*E7 -> 68248.443 | F27: =F26*F7 -> 77478.385 | G27: =G26*G7 -> 84221.235 | H27: =H26*H7 -> 101671.35 | I27: =I26*I7 -> 116395.62 | J27: =J26*J7 -> 120506.45 | ... Q27: =Q26*Q7 -> 202529.24
A30: # | B30: Cost Driver
B32: COGS | C32: ='Historical FS'!C8 -> 38281 | D32: ='Historical FS'!D8 -> 40331 | E32: ='Historical FS'!E8 -> 48850 | F32: ='Historical FS'!F8 -> 53988 | G32: ='Historical FS'!G8 -> 57966 | H32: ='Historical FS'!H8 -> 71916 | I32: ='Historical FS'!I8 -> 88211 | J32: ='Historical FS'!J8 -> 91832 | ... L32: ='Historical FS'!L8 -> 106285 | M32: =M34+M43 -> 113755.42 | N32: =N34+N43 -> 121772.55 | O32: =O34+O43 -> 130378.12 | P32: =P34+P43 -> 139617.15 | Q32: =Q34+Q43 -> 149538.27
B34: Employee Cost | C34: ='DATA Sheet'!B22 -> 30953 | D34: ='DATA Sheet'!C22 -> 32481 | E34: ='DATA Sheet'!D22 -> 38303 | F34: ='DATA Sheet'!E22 -> 42442 | G34: ='DATA Sheet'!F22 -> 45185 | H34: ='DATA Sheet'!G22 -> 51675 | I34: ='DATA Sheet'!H22 -> 62779 | J34: ='DATA Sheet'!I22 -> 65155 | ... L34: ='DATA Sheet'!K22 -> 73257 | M34: =M39*M36 -> 77704.122 | N34: =N39*N36 -> 82421.21 | O34: =O39*O36 -> 87424.653 | P34: =P39*P36 -> 92731.833 | Q34: =Q39*Q36 -> 98361.19
B36: Head Count | C36: =KPIs!D6 -> 200364 | D36: =KPIs!E6 -> 204107 | E36: =KPIs!F6 -> 228123 | F36: =KPIs!G6 -> 242371 | G36: =KPIs!H6 -> 259619 | H36: =KPIs!I6 -> 314015 | I36: =KPIs!J6 -> 343234 | J36: =KPIs!K6 -> 317240 | ... L36: =KPIs!M6 -> 328594 | M36: =L36*(1+M37) -> 334423.3 | N36: =M36*(1+N37) -> 340356.01 | O36: =N36*(1+O37) -> 346393.96 | P36: =O36*(1+P37) -> 352539.03 | Q36: =P36*(1+Q37) -> 358793.12
B37: Growth | C37: =C36/KPIs!C6-1 -> 0.032569933 | D37: =D36/C36-1 -> 0.018681001 | E37: =E36/D36-1 -> 0.11766377 | F37: =F36/E36-1 -> 0.062457534 | G37: =G36/F36-1 -> 0.071163629 | H37: =H36/G36-1 -> 0.20952242 | I37: =I36/H36-1 -> 0.093049695 | J37: =J36/I36-1 -> -0.075732591 | K37: =K36/J36-1 -> 0.019978565 | L37: =L36/K36-1 -> 0.015501672 | M37: =AVERAGE($K37:$L37)+Scenarios!$H$7 -> 0.017740119 | N37: =AVERAGE($K37:$L37)+Scenarios!$H$7 -> 0.017740119 | O37: =AVERAGE($K37:$L37)+Scenarios!$H$7 -> 0.017740119 | P37: =AVERAGE($K37:$L37)+Scenarios!$H$7 -> 0.017740119 | Q37: =AVERAGE($K37:$L37)+Scenarios!$H$7 -> 0.017740119
B39: Avereage Employee cost\ | C39: =C34/C36 -> 0.15448384 | D39: =D34/D36 -> 0.15913712 | E39: =E34/E36 -> 0.16790503 | F39: =F34/F36 -> 0.17511171 | G39: =G34/G36 -> 0.1740435 | H39: =H34/H36 -> 0.1645622 | I39: =I34/I36 -> 0.18290437 | J39: =J34/J36 -> 0.20538078 | ... L39: =L34/L36 -> 0.22294077 | M39: =L39*(1+M40) -> 0.2323526 | N39: =M39*(1+N40) -> 0.24216176 | O39: =N39*(1+O40) -> 0.25238504 | P39: =O39*(1+P40) -> 0.2630399 | Q39: =P39*(1+Q40) -> 0.27414459
B40: Growth | C40: =C39/KPIs!D17-1 -> 0.49839709 | D40: =D39/C39-1 -> 0.030121467 | E40: =E39/D39-1 -> 0.055096601 | F40: =F39/E39-1 -> 0.042921139 | G40: =G39/F39-1 -> -0.0061001443 | H40: =H39/G39-1 -> -0.054476609 | I40: =I39/H39-1 -> 0.11146042 | J40: =J39/I39-1 -> 0.12288613 | K40: =K39/J39-1 -> 0.015458133 | L40: =L39/K39-1 -> 0.068975299 | M40: =AVERAGE($K40:$L40)+Scenarios!$H$8 -> 0.042216716 | N40: =AVERAGE($K40:$L40)+Scenarios!$H$8 -> 0.042216716 | O40: =AVERAGE($K40:$L40)+Scenarios!$H$8 -> 0.042216716 | P40: =AVERAGE($K40:$L40)+Scenarios!$H$8 -> 0.042216716 | Q40: =AVERAGE($K40:$L40)+Scenarios!$H$8 -> 0.042216716
B43: Other COGS | C43: =C32-C34 -> 7328 | D43: =D32-D34 -> 7850 | E43: =E32-E34 -> 10547 | F43: =F32-F34 -> 11546 | G43: =G32-G34 -> 12781 | H43: =H32-H34 -> 20241 | I43: =I32-I34 -> 25432 | J43: =J32-J34 -> 26677 | ... L43: =L32-L34 -> 33028 | M43: =L43*(1+M44) -> 36051.299 | N43: =M43*(1+N44) -> 39351.343 | O43: =N43*(1+O44) -> 42953.465 | P43: =O43*(1+P44) -> 46885.316 | Q43: =P43*(1+Q44) -> 51177.078
C44: =C43/'P&L'!D18-1 -> 0.027154327 | D44: =D43/C43-1 -> 0.071233624 | E44: =E43/D43-1 -> 0.34356688 | F44: =F43/E43-1 -> 0.094718877 | G44: =G43/F43-1 -> 0.10696345 | H44: =H43/G43-1 -> 0.5836789 | I44: =I43/H43-1 -> 0.25645966 | J44: =J43/I43-1 -> 0.048954074 | K44: =K43/J43-1 -> 0.13067436 | L44: =L43/K43-1 -> 0.094983921 | M44: =AVERAGE($J44:$L44) -> 0.091537453 | N44: =AVERAGE($J44:$L44) -> 0.091537453 | O44: =AVERAGE($J44:$L44) -> 0.091537453 | P44: =AVERAGE($J44:$L44) -> 0.091537453 | Q44: =AVERAGE($J44:$L44) -> 0.091537453
B47: SG&A | C47: ='Historical FS'!C15 -> 3801 | D47: ='Historical FS'!D15 -> 4313 | E47: ='Historical FS'!E15 -> 5583 | F47: ='Historical FS'!F15 -> 5024 | G47: ='Historical FS'!G15 -> 3489 | H47: ='Historical FS'!H15 -> 4196 | I47: ='Historical FS'!I15 -> 5109 | J47: ='Historical FS'!J15 -> 5344 | ... L47: ='Historical FS'!L15 -> 6521 | M47: =M48*M7 -> 6694.3954 | N47: =N48*N7 -> 7219.3921 | O47: =O48*O7 -> 7785.5607 | P47: =P48*P7 -> 8396.1302 | Q47: =Q48*Q7 -> 9054.5826
B48: % of sales | C48: =C47/C7 -> 0.0641097 | D48: =D47/D7 -> 0.069630778 | E48: =E47/E7 -> 0.076367516 | F48: =F47/F7 -> 0.063557124 | G48: =G47/G7 -> 0.040611323 | H48: =H47/H7 -> 0.040369444 | I48: =I47/I7 -> 0.041196962 | J48: =J47/J7 -> 0.041447884 | ... L48: =L47/L7 -> 0.04381833 | M48: =AVERAGE($J48:$L48) -> 0.041712259 | N48: =AVERAGE($J48:$L48) -> 0.041712259 | O48: =AVERAGE($J48:$L48) -> 0.041712259 | P48: =AVERAGE($J48:$L48) -> 0.041712259 | Q48: =AVERAGE($J48:$L48) -> 0.041712259
A51: # | B51: Depreciation
B53: Fixed Assets | C53: ='Historical FS'!C53 -> 8605 | D53: ='Historical FS'!D53 -> 9157 | E53: ='Historical FS'!E53 -> 10497 | F53: ='Historical FS'!F53 -> 13974 | G53: ='Historical FS'!G53 -> 14599 | H53: ='Historical FS'!H53 -> 14938 | I53: ='Historical FS'!I53 -> 15431 | J53: ='Historical FS'!J53 -> 14327 | ... L53: ='Historical FS'!L53 -> 13836 | M53: =M7/M54 -> 16059.723 | N53: =N7/N54 -> 17319.18 | O53: =O7/O54 -> 18677.408 | P53: =P7/P54 -> 20142.152 | Q53: =Q7/Q54 -> 21721.766
B54: FA turnover ratio | C54: ='Ratio Analysis'!C34 -> 6.8900639 | D54: ='Ratio Analysis'!D34 -> 6.7643333 | E54: ='Ratio Analysis'!E34 -> 6.9645613 | F54: ='Ratio Analysis'!F34 -> 5.6567196 | G54: ='Ratio Analysis'!G34 -> 5.8847866 | H54: ='Ratio Analysis'!H34 -> 6.9580935 | I54: ='Ratio Analysis'!I34 -> 8.0366794 | J54: ='Ratio Analysis'!J34 -> 8.999302 | ... L54: ='Ratio Analysis'!L34 -> 10.755927 | M54: =AVERAGE($J54:$L54) -> 9.9933153 | N54: =AVERAGE($J54:$L54) -> 9.9933153 | O54: =AVERAGE($J54:$L54) -> 9.9933153 | P54: =AVERAGE($J54:$L54) -> 9.9933153 | Q54: =AVERAGE($J54:$L54) -> 9.9933153
B56: Depreciation | C56: ='Historical FS'!C25 -> 1331 | D56: ='Historical FS'!D25 -> 1408 | E56: ='Historical FS'!E25 -> 1599 | F56: ='Historical FS'!F25 -> 2144 | G56: ='Historical FS'!G25 -> 2321 | H56: ='Historical FS'!H25 -> 2429 | I56: ='Historical FS'!I25 -> 2753 | J56: ='Historical FS'!J25 -> 2944 | ... L56: ='Historical FS'!L25 -> 2394 | M56: =M57*M7 -> 3107.8389 | N56: =N57*N7 -> 3351.566 | O56: =O57*O7 -> 3614.4069 | P56: =P57*P7 -> 3897.8606 | Q56: =Q57*Q7 -> 4203.5438
B57: % of sales | C57: =C56/C7 -> 0.022449358 | D57: =D56/D7 -> 0.022731309 | E57: =E56/E7 -> 0.021872051 | F57: =F56/F7 -> 0.027123104 | G57: =G56/G7 -> 0.027016016 | H57: =H56/H7 -> 0.023369251 | I57: =I56/I7 -> 0.022199107 | J57: =J56/J7 -> 0.022833565 | ... L57: =L56/L7 -> 0.016086656 | M57: =AVERAGE($J57:$L57) -> 0.019364703 | N57: =AVERAGE($J57:$L57) -> 0.019364703 | O57: =AVERAGE($J57:$L57) -> 0.019364703 | P57: =AVERAGE($J57:$L57) -> 0.019364703 | Q57: =AVERAGE($J57:$L57) -> 0.019364703
A60: # | B60: borrowings
B62: Borrowings | C62: ='Historical FS'!C47 -> 0 | D62: ='Historical FS'!D47 -> 0 | E62: ='Historical FS'!E47 -> 0 | F62: ='Historical FS'!F47 -> 3165 | G62: ='Historical FS'!G47 -> 3854 | H62: ='Historical FS'!H47 -> 3786 | I62: ='Historical FS'!I47 -> 4266 | J62: ='Historical FS'!J47 -> 3766 | ... L62: ='Historical FS'!L47 -> 3749 | M62: =AVERAGE($J$62:$L$62) -> 3658 | N62: =AVERAGE($J$62:$L$62) -> 3658 | O62: =AVERAGE($J$62:$L$62) -> 3658 | P62: =AVERAGE($J$62:$L$62) -> 3658 | Q62: =AVERAGE($J$62:$L$62) -> 3658
B65: Interest | C65: ='Historical FS'!C22 -> 0 | D65: ='Historical FS'!D22 -> 0 | E65: ='Historical FS'!E22 -> 0 | F65: ='Historical FS'!F22 -> 114 | G65: ='Historical FS'!G22 -> 126 | H65: ='Historical FS'!H22 -> 128 | I65: ='Historical FS'!I22 -> 157 | J65: ='Historical FS'!J22 -> 277 | ... L65: ='Historical FS'!L22 -> 207 | M65: =M66*M62 -> 234.91537 | N65: =N66*N62 -> 234.91537 | O65: =O66*O62 -> 234.91537 | P65: =P66*P62 -> 234.91537 | Q65: =Q66*Q62 -> 234.91537
B66: Effective rate | F66: =F65/F62 -> 0.036018957 | G66: =G65/G62 -> 0.032693306 | H66: =H65/H62 -> 0.033808769 | I66: =I65/I62 -> 0.036802625 | J66: =J65/J62 -> 0.073552841 | K66: =K65/K62 -> 0.063891298 | L66: =L65/L62 -> 0.055214724 | M66: =AVERAGE($J66:$L66) -> 0.064219621 | N66: =AVERAGE($J66:$L66) -> 0.064219621 | O66: =AVERAGE($J66:$L66) -> 0.064219621 | P66: =AVERAGE($J66:$L66) -> 0.064219621 | Q66: =AVERAGE($J66:$L66) -> 0.064219621
A69: # | B69: Others
B71: Other Income | C71: ='Historical FS'!C28 -> 3062 | D71: ='Historical FS'!D28 -> 4019 | E71: ='Historical FS'!E28 -> 2852 | F71: ='Historical FS'!F28 -> 2700 | G71: ='Historical FS'!G28 -> 2467 | H71: ='Historical FS'!H28 -> 3224 | I71: ='Historical FS'!I28 -> 3859 | J71: ='Historical FS'!J28 -> 7417 | ... L71: ='Historical FS'!L28 -> 5345 | M71: =M72*M7 -> 6871.7211 | N71: =N72*N7 -> 7410.6243 | O71: =O72*O7 -> 7991.79 | P71: =P72*P7 -> 8618.5327 | Q71: =Q72*Q7 -> 9294.4266
B72: % of sales | C72: =C71/C7 -> 0.05164533 | D72: =D71/D7 -> 0.064884325 | E72: =E71/E7 -> 0.039011312 | F72: =F71/F7 -> 0.034156894 | G72: =G71/G7 -> 0.02871543 | H72: =H71/H7 -> 0.031017895 | I72: =I71/I7 -> 0.031117454 | J72: =J71/J7 -> 0.057526002 | ... L72: =L71/L7 -> 0.035916113 | M72: =AVERAGE($J72:$L72) -> 0.042817162 | N72: =AVERAGE($J72:$L72) -> 0.042817162 | O72: =AVERAGE($J72:$L72) -> 0.042817162 | P72: =AVERAGE($J72:$L72) -> 0.042817162 | Q72: =AVERAGE($J72:$L72) -> 0.042817162
...

Sheet Forecasted FS
B2: ='DATA Sheet'!B1&" Forecasted FS" -> INFOSYS LTD Forecasted FS
B3: Years (As on March) | C3: 2027 | D3: =C3+1 -> 2028 | E3: =D3+1 -> 2029 | F3: =E3+1 -> 2030 | G3: =F3+1 -> 2031
A5: # | B5: Income Statement | I5: Scenario | J5: =DASHBOARD!D2 -> Base | L5: Pessmistic | M5: Base | N5: Optmistic
B7: Sales | C7: ='Forecast Drivers'!M7 -> 160489.88 | D7: ='Forecast Drivers'!N7 -> 173076.03 | E7: ='Forecast Drivers'!O7 -> 186649.22 | F7: ='Forecast Drivers'!P7 -> 201286.87 | G7: ='Forecast Drivers'!Q7 -> 217072.46
B9: COGS | C9: ='Forecast Drivers'!M32 -> 113755.42 | D9: ='Forecast Drivers'!N32 -> 121772.55 | E9: ='Forecast Drivers'!O32 -> 130378.12 | F9: ='Forecast Drivers'!P32 -> 139617.15 | G9: ='Forecast Drivers'!Q32 -> 149538.27
B11: Gross profit | C11: =C7-C9 -> 46734.458 | D11: =D7-D9 -> 51303.474 | E11: =E7-E9 -> 56271.105 | F11: =F7-F9 -> 61669.725 | G11: =G7-G9 -> 67534.189
B12: Gross margin | C12: =C11/C7 -> 0.29119879 | D12: =D11/D7 -> 0.29642161 | E12: =E11/E7 -> 0.30148052 | F12: =F11/F7 -> 0.30637728 | G12: =G11/G7 -> 0.31111358
B15: SG&A | C15: ='Forecast Drivers'!M47 -> 6694.3954 | D15: ='Forecast Drivers'!N47 -> 7219.3921 | E15: ='Forecast Drivers'!O47 -> 7785.5607 | F15: ='Forecast Drivers'!P47 -> 8396.1302 | G15: ='Forecast Drivers'!Q47 -> 9054.5826
B17: EBITDA | C17: =C11-C15 -> 40040.063 | D17: =D11-D15 -> 44084.082 | E17: =E11-E15 -> 48485.545 | F17: =F11-F15 -> 53273.595 | G17: =G11-G15 -> 58479.607
B18: % of sales | C18: =C17/C7 -> 0.24948653 | D18: =D17/D7 -> 0.25470935 | E18: =E17/E7 -> 0.25976826 | F18: =F17/F7 -> 0.26466502 | G18: =G17/G7 -> 0.26940132
B20: Depreciation | C20: ='Forecast Drivers'!M56 -> 3107.8389 | D20: ='Forecast Drivers'!N56 -> 3351.566 | E20: ='Forecast Drivers'!O56 -> 3614.4069 | F20: ='Forecast Drivers'!P56 -> 3897.8606 | G20: ='Forecast Drivers'!Q56 -> 4203.5438
B23: Interest | C23: ='Forecast Drivers'!M65 -> 234.91537 | D23: ='Forecast Drivers'!N65 -> 234.91537 | E23: ='Forecast Drivers'!O65 -> 234.91537 | F23: ='Forecast Drivers'!P65 -> 234.91537 | G23: ='Forecast Drivers'!Q65 -> 234.91537
B26: Other Income | C26: ='Forecast Drivers'!M71 -> 6871.7211 | D26: ='Forecast Drivers'!N71 -> 7410.6243 | E26: ='Forecast Drivers'!O71 -> 7991.79 | F26: ='Forecast Drivers'!P71 -> 8618.5327 | G26: ='Forecast Drivers'!Q71 -> 9294.4266
B28: PBT | C28: =C17-C20-C23+C26 -> 43569.029 | D28: =D17-D20-D23+D26 -> 47908.225 | E28: =E17-E20-E23+E26 -> 52628.012 | F28: =F17-F20-F23+F26 -> 57759.351 | G28: =G17-G20-G23+G26 -> 63335.574
B30: Tax | C30: =C28*'Forecast Drivers'!M89 -> 10966.325 | D30: =D28*'Forecast Drivers'!N89 -> 12058.5 | E30: =E28*'Forecast Drivers'!O89 -> 13246.471 | F30: =F28*'Forecast Drivers'!P89 -> 14538.029 | G30: =G28*'Forecast Drivers'!Q89 -> 15941.564
B32: Net profit | C32: =C28-C30 -> 32602.705 | D32: =D28-D30 -> 35849.725 | E32: =E28-E30 -> 39381.542 | F32: =F28-F30 -> 43221.323 | G32: =G28-G30 -> 47394.01
B33: Net Margin | C33: =C32/C7 -> 0.20314493 | D33: =D32/D7 -> 0.20713281 | E33: =E32/E7 -> 0.21099226 | F33: =F32/F7 -> 0.21472499 | G33: =G32/G7 -> 0.21833267
A37: # | B37: Balance Sheet
B39: Equity Share Capital | C39: ='Historical FS'!L45 -> 2027 | D39: =C39 -> 2027 | E39: =D39 -> 2027 | F39: =E39 -> 2027 | G39: =F39 -> 2027
B40: Reserves | C40: ='Historical FS'!L46+C32*'Forecast Drivers'!M87 -> 89003.817 | D40: =C40+D32*'Forecast Drivers'!N87 -> 100172.19 | E40: =D40+E32*'Forecast Drivers'!O87 -> 112440.84 | F40: =E40+F32*'Forecast Drivers'!P87 -> 125905.7 | G40: =F40+G32*'Forecast Drivers'!Q87 -> 140670.5
B41: Borrowings | C41: ='Forecast Drivers'!M62 -> 3658 | D41: ='Forecast Drivers'!N62 -> 3658 | E41: ='Forecast Drivers'!O62 -> 3658 | F41: ='Forecast Drivers'!P62 -> 3658 | G41: ='Forecast Drivers'!Q62 -> 3658
B42: Other Liabilities | C42: ='Forecast Drivers'!M78 -> 40518.196 | D42: ='Forecast Drivers'!N78 -> 43741.634 | E42: ='Forecast Drivers'!O78 -> 47222.063 | F42: ='Forecast Drivers'!P78 -> 50980.022 | G42: ='Forecast Drivers'!Q78 -> 55037.695
B44: Total Liablities | C44: =SUM(C39:C42) -> 135207.01 | D44: =SUM(D39:D42) -> 149598.82 | E44: =SUM(E39:E42) -> 165347.9 | F44: =SUM(F39:F42) -> 182570.72 | G44: =SUM(G39:G42) -> 201393.19
B47: Fixed Assets | C47: ='Forecast Drivers'!M53 -> 16059.723 | D47: ='Forecast Drivers'!N53 -> 17319.18 | E47: ='Forecast Drivers'!O53 -> 18677.408 | F47: ='Forecast Drivers'!P53 -> 20142.152 | G47: ='Forecast Drivers'!Q53 -> 21721.766
B48: Capital Work in Progress | C48: ='Historical FS'!L54 -> 512 | D48: =C48 -> 512 | E48: =D48 -> 512 | F48: =E48 -> 512 | G48: =F48 -> 512
B49: Investments | C49: ='Historical FS'!L55 -> 38075 | D49: =C49 -> 38075 | E49: =D49 -> 38075 | F49: =E49 -> 38075 | G49: =F49 -> 38075
B51: Total Non Current Assets | C51: =SUM(C47:C49) -> 54646.723 | D51: =SUM(D47:D49) -> 55906.18 | E51: =SUM(E47:E49) -> 57264.408 | F51: =SUM(F47:F49) -> 58729.152 | G51: =SUM(G47:G49) -> 60308.766
B53: Trade receivables | C53: ='Forecast Drivers'!M95 -> 31686.117 | D53: ='Forecast Drivers'!N95 -> 34171.048 | E53: ='Forecast Drivers'!O95 -> 36850.854 | F53: ='Forecast Drivers'!P95 -> 39740.82 | G53: ='Forecast Drivers'!Q95 -> 42857.427
B54: Cash Equivalents | C54: =C87 -> 12517.331 | D54: =D87 -> 20313.529 | E54: =E87 -> 28949.746 | F54: =F87 -> 38501.896 | G54: =G87 -> 49052.13
B55: Loans and Advances | C55: ='Forecast Drivers'!M102 -> 6253.8823 | D55: ='Forecast Drivers'!N102 -> 6744.3325 | E55: ='Forecast Drivers'!O102 -> 7273.2454 | F55: ='Forecast Drivers'!P102 -> 7843.6374 | G55: ='Forecast Drivers'!Q102 -> 8458.7614
B56: Other asset items | C56: ='Forecast Drivers'!M75 -> 30102.958 | D56: ='Forecast Drivers'!N75 -> 32463.732 | E56: ='Forecast Drivers'!O75 -> 35009.646 | F56: ='Forecast Drivers'!P75 -> 37755.218 | G56: ='Forecast Drivers'!Q75 -> 40716.107
B58: Total Current Assets | C58: =SUM(C53:C56) -> 80560.289 | D58: =SUM(D53:D56) -> 93692.641 | E58: =SUM(E53:E56) -> 108083.49 | F58: =SUM(F53:F56) -> 123841.57 | G58: =SUM(G53:G56) -> 141084.43
B60: Total assets | C60: =C58+C51 -> 135207.01 | D60: =D58+D51 -> 149598.82 | E60: =E58+E51 -> 165347.9 | F60: =F58+F51 -> 182570.72 | G60: =G58+G51 -> 201393.19
B62: Check | C62: =C60=C44 -> TRUE | D62: =D60=D44 -> TRUE | E62: =E60=E44 -> TRUE | F62: =F60=F44 -> TRUE | G62: =G60=G44 -> TRUE
A64: # | B64: Cashflow Statement
B66: Operating Activities
B68: Net profit | C68: =C32 -> 32602.705 | D68: =D32 -> 35849.725 | E68: =E32 -> 39381.542 | F68: =F32 -> 43221.323 | G68: =G32 -> 47394.01
B69: Depreciation | C69: =C20 -> 3107.8389 | D69: =D20 -> 3351.566 | E69: =E20 -> 3614.4069 | F69: =F20 -> 3897.8606 | G69: =G20 -> 4203.5438
B70: Changes In the Working Capital | C70: =-((C56+C55+C53-C42)-('Historical FS'!L62+'Historical FS'!L61+'Historical FS'!L59-'Historical FS'!L48)) -> -4051.7623 | D70: =-((D56+D55+D53-D42)-(C56+C55+C53-C42)) -> -2112.7162 | E70: =-((E56+E55+E53-E42)-(D56+D55+D53-D42)) -> -2274.2039 | F70: =-((F56+F55+F53-F42)-(E56+E55+E53-E42)) -> -2447.9716 | G70: =-((G56+G55+G53-G42)-(F56+F55+F53-F42)) -> -2634.9473
B71: Direct tax
...

Sheet Comprables
A1: 0

Sheet EV-EBITDA
B3: Comparables
B4: Particulars | C4: Infosys | D4: TCS | E4: HCL | F4: Wipro
B6: Market CAP | C6: ='DATA Sheet'!B9 -> 464241.67 | D6: 867347 | E6: 355979 | F6: 183298
B7: Debt | C7: ='Historical FS'!L47 -> 3749 | D7: 11283 | E7: 988 | F7: 20291
B8: Cash | C8: ='Historical FS'!L60 -> 8727 | D8: 12908 | E8: 3794 | F8: 10556
B9: EV | C9: =C6+C7-C8 -> 459263.67 | D9: =D6+D7-D8 -> 865722 | E9: =E6+E7-E8 -> 353173 | F9: =F6+F7-F8 -> 193033
B12: EBITDA | C12: ='Historical FS'!L18 -> 36013 | D12: 74079 | E12: 17059 | F12: 18211
B14: EV/EBITDA | C14: =C9/C12 -> 12.752719 | D14: =D9/D12 -> 11.68647 | E14: =E9/E12 -> 20.703031 | F14: =F9/F12 -> 10.599802

Sheet DCF Valuation >>

Sheet DCF
